#VRML_SIM R2022a utf8
WorldInfo {
  basicTimeStep 16
  contactProperties [
    ContactProperties {
      material2 "dumbell"
    }
  ]
}
Viewpoint {
  orientation 0.18293475237065815 0.7653690746600578 -0.6170454245265035 1.1000845853088062
  position -1.7649966333757758 1.5655309044473853 2.677140243390226
}
TexturedBackground {
}
TexturedBackgroundLight {
}
Floor {
  size 1 1
}
Solid {
  translation -0.00612779 0.463093 0.05
  rotation 0 1 0 0.006545030000028386
  children [
    Shape {
      appearance PBRAppearance {
        baseColor 0 0 1
        roughness 1
        metalness 0
      }
      geometry Box {
        size 1 0.1 0.1
      }
    }
  ]
  name "solid(1)"
}
Solid {
  translation -0.451847 0.00554167 0.05
  rotation -0.003272500951368443 0.003272490951365536 0.999989290712904 1.57081
  children [
    Shape {
      appearance PBRAppearance {
        baseColor 0 0 1
        roughness 1
        metalness 0
      }
      geometry Box {
        size 1 0.1 0.1
      }
    }
  ]
  name "solid(3)"
}
Solid {
  translation 0.443776 0.0142597 0.05
  rotation -0.003272500951368443 0.003272490951365536 0.999989290712904 1.57081
  children [
    Shape {
      appearance PBRAppearance {
        baseColor 0 0 1
        roughness 1
        metalness 0
      }
      geometry Box {
        size 1 0.1 0.1
      }
    }
  ]
  name "solid(4)"
}
Solid {
  translation -0.00216996 -0.449267 0.05
  rotation 0 1 0 0.00654503
  children [
    Shape {
      appearance PBRAppearance {
        baseColor 0 0 1
        roughness 1
        metalness 0
      }
      geometry Box {
        size 1 0.1 0.1
      }
    }
  ]
  name "solid(2)"
}
Robot {
  children [
    HingeJoint {
      jointParameters HingeJointParameters {
      }
      device [
        RotationalMotor {
        }
      ]
    }
    Shape {
      appearance PBRAppearance {
        baseColor 1 0 0
        roughness 1
        metalness 0
      }
      geometry Box {
        size 0.2 0.1 0.05
      }
    }
  ]
  physics Physics {
  }
}
