#VRML_SIM R2022a utf8
WorldInfo {
  basicTimeStep 64
  contactProperties [
    ContactProperties {
      material2 "dumbell"
    }
  ]
}
Viewpoint {
  orientation -0.23592904327860725 0.016086530369051458 0.9716371288080374 3.2127943154785306
  position 1.847181587683104 0.21952667184823038 0.9667592821603505
}
TexturedBackground {
}
TexturedBackgroundLight {
}
Floor {
  size 1 1
}
Solid {
  translation -0.446602 0.00246132 0.05
  rotation 0 0 -1 1.5708
  children [
    Shape {
      appearance PBRAppearance {
        baseColor 0 0 1
        roughness 1
        metalness 0
      }
      geometry Box {
        size 1 0.1 0.1
      }
    }
  ]
  name "solid(1)"
}
Solid {
  translation 0.449027 0.00230536 0.05
  rotation 0 0 -1 1.5708
  children [
    Shape {
      appearance PBRAppearance {
        baseColor 0 0 1
        roughness 1
        metalness 0
      }
      geometry Box {
        size 1 0.1 0.1
      }
    }
  ]
  name "solid(4)"
}
Robot {
  translation -0.00543624 0.0282559 0.1
  rotation 0 0 1 0.425424
  children [
    DistanceSensor {
      translation 0.1 0.02 0
      rotation 0 0 1 -1.27
      children [
        DEF Sensor Shape {
          appearance PBRAppearance {
            baseColor 0 0 1
            roughness 1
            metalness 0
          }
          geometry Box {
            size 0.01 0.01 0.01
          }
        }
      ]
      name "ds_left"
      boundingObject USE Sensor
      physics Physics {
      }
    }
    DistanceSensor {
      translation 0.1 -0.02 0
      rotation 0 0 1 -1.87
      children [
        DEF Sensor Shape {
          appearance PBRAppearance {
            baseColor 0 0 1
            roughness 1
            metalness 0
          }
          geometry Box {
            size 0.01 0.01 0.01
          }
        }
      ]
      name "ds_right"
      boundingObject USE Sensor
      physics Physics {
      }
    }
    HingeJoint {
      jointParameters HingeJointParameters {
        axis 0 1 0
        anchor 0.05 0.06 0
      }
      device [
        RotationalMotor {
          name "wheel1"
        }
      ]
      endPoint Solid {
        translation 0.050000215688449264 0.06000000001123594 7.678174730663562e-06
        rotation 0.9999999999999999 2.8235261266418484e-14 2.0343588444148565e-14 1.5707999999930056
        children [
          Shape {
            appearance PBRAppearance {
              baseColor 0 1 0
              roughness 1
              metalness 0
            }
            geometry DEF Wheel_Geometry Cylinder {
              height 0.02
              radius 0.04
            }
          }
        ]
        boundingObject USE Wheel_Geometry
        physics Physics {
        }
      }
    }
    HingeJoint {
      jointParameters HingeJointParameters {
        axis 0 1 0
        anchor 0.05 -0.06 1.22354e-07
      }
      device [
        RotationalMotor {
          name "wheel2"
        }
      ]
      endPoint Solid {
        translation 0.05000021567240062 -0.05999999998883378 7.80046913419121e-06
        rotation 0.9999999999999998 -9.589759202732607e-09 -9.589788893776085e-09 1.5707953071797367
        children [
          Shape {
            appearance PBRAppearance {
              baseColor 0 1 0
              roughness 1
              metalness 0
            }
            geometry Cylinder {
              height 0.02
              radius 0.04
            }
          }
        ]
        name "solid(1)"
        boundingObject USE Wheel_Geometry
        physics Physics {
        }
      }
    }
    HingeJoint {
      jointParameters HingeJointParameters {
        axis 0 1 0
        anchor -0.05 0.06 4.68944e-14
      }
      device [
        RotationalMotor {
          name "wheel3"
        }
      ]
      endPoint Solid {
        translation -0.05000040775791288 0.06000000000372621 7.658060009932218e-06
        rotation 0.9999999999999998 -9.589769555401596e-09 -9.589799790967372e-09 1.57079530717943
        children [
          Shape {
            appearance PBRAppearance {
              baseColor 0 1 0
              roughness 1
              metalness 0
            }
            geometry Cylinder {
              height 0.02
              radius 0.04
            }
          }
        ]
        name "solid(2)"
        boundingObject USE Wheel_Geometry
        physics Physics {
        }
      }
    }
    HingeJoint {
      jointParameters HingeJointParameters {
        axis 0 1 0
        anchor -0.05 -0.06 1.22354e-07
      }
      device [
        RotationalMotor {
          name "wheel4"
        }
      ]
      endPoint Solid {
        translation -0.050000407752760025 -0.059999999996258976 7.780354359086647e-06
        rotation 0.9999999999999998 -9.589769619925862e-09 -9.589799727188648e-09 1.5707953071794276
        children [
          Shape {
            appearance PBRAppearance {
              baseColor 0 1 0
              roughness 1
              metalness 0
            }
            geometry Cylinder {
              height 0.02
              radius 0.04
            }
          }
        ]
        name "solid(3)"
        boundingObject USE Wheel_Geometry
        physics Physics {
        }
      }
    }
    DEF Body Shape {
      appearance PBRAppearance {
        baseColor 1 0 0
        roughness 1
        metalness 0
      }
      geometry DEF Body_Geometry Box {
        size 0.2 0.1 0.05
      }
    }
  ]
  physics Physics {
  }
  controller "four_wheeled_collision_avoidance"
  controllerArgs [
    ""
  ]
}
Solid {
  translation 0.000510046 -0.449895 0.05
  rotation 0 1 0 0.006545030000028386
  children [
    Shape {
      appearance PBRAppearance {
        baseColor 0 0 1
        roughness 1
        metalness 0
      }
      geometry Box {
        size 1 0.1 0.1
      }
    }
  ]
  name "solid(3)"
}
Solid {
  translation 8.93125e-05 0.455265 0.05
  rotation 0 1 0 0.006545030000028386
  children [
    Shape {
      appearance PBRAppearance {
        baseColor 0 0 1
        roughness 1
        metalness 0
      }
      geometry Box {
        size 1 0.1 0.1
      }
    }
  ]
  name "solid(2)"
}
