#VRML_SIM R2022a utf8
WorldInfo {
  basicTimeStep 64
  contactProperties [
    ContactProperties {
      material2 "dumbell"
    }
  ]
}
Viewpoint {
  orientation -0.6194173938033924 0.5925761066920838 0.5149520851802285 2.302258650392571
  position 0.005078488824831917 0.4703486203123675 3.260770247231822
}
TexturedBackground {
}
TexturedBackgroundLight {
}
SpotLight {
  attenuation 0 0 1
  beamWidth 1
  cutOffAngle 1.5
  direction 0 1 -1
  intensity 4
  location 1 1 1
}
PointLight {
  attenuation 0 0 1
  location 0 0.3 0
  on FALSE
}
DirectionalLight {
  direction 0 -1 0
  on FALSE
}
Floor {
  size 1 1
}
Solid {
  translation 0.478935819145198 0.04516980454087883 0.049223674279199624
  rotation 1.19436e-11 2.09709e-11 1 1.5904
  children [
    Shape {
      appearance PBRAppearance {
        baseColor 0 0 1
        roughness 1
        metalness 0
      }
      geometry DEF WALL_GEOMETRY Box {
        size 1.1 0.1 0.1
      }
    }
  ]
  name "solid(2)"
  boundingObject Box {
    size 0.1 0.1 0.1
  }
  physics Physics {
  }
}
Solid {
  translation -0.460183 0.0166555 0.0492237
  rotation 1.2598033413260165e-11 2.114351982203433e-11 1 1.5511319456926784
  children [
    Shape {
      appearance PBRAppearance {
        baseColor 0 0 1
        roughness 1
        metalness 0
      }
      geometry DEF WALL_GEOMETRY Box {
        size 1.1 0.1 0.1
      }
    }
  ]
  name "solid(3)"
  boundingObject Box {
    size 0.1 0.1 0.1
  }
  physics Physics {
  }
}
Solid {
  translation 0.0119466 0.51685 0.0492237
  rotation 2.54708e-09 6.8962e-10 1 0.0130602
  children [
    Shape {
      appearance PBRAppearance {
        baseColor 0 0 1
        roughness 1
        metalness 0
      }
      geometry DEF WALL_GEOMETRY Box {
        size 1.1 0.1 0.1
      }
    }
  ]
  name "solid(4)"
  boundingObject Box {
    size 0.1 0.1 0.1
  }
  physics Physics {
  }
}
Solid {
  translation -0.00728932 -0.460551 0.0492237
  rotation 2.54708e-09 6.8962e-10 1 0.0130602
  children [
    Shape {
      appearance PBRAppearance {
        baseColor 0 0 1
        roughness 1
        metalness 0
      }
      geometry DEF WALL_GEOMETRY Box {
        size 1.1 0.1 0.1
      }
    }
  ]
  name "solid(1)"
  boundingObject Box {
    size 0.1 0.1 0.1
  }
  physics Physics {
  }
}
Robot {
  translation -0.00543624 0.0282559 0.1
  children [
    DistanceSensor {
      translation 0.1 0.02 0
      rotation 0 0 1 -1.27
      children [
        DEF Sensor Shape {
          appearance PBRAppearance {
            baseColor 0 0 1
            roughness 1
            metalness 0
          }
          geometry Box {
            size 0.01 0.01 0.01
          }
        }
      ]
      name "ds_left"
      boundingObject USE Sensor
      physics Physics {
      }
    }
    DistanceSensor {
      translation 0.1 -0.02 0
      rotation 0 0 1 -1.87
      children [
        DEF Sensor Shape {
          appearance PBRAppearance {
            baseColor 0 0 1
            roughness 1
            metalness 0
          }
          geometry Box {
            size 0.01 0.01 0.01
          }
        }
      ]
      name "ds_right"
      boundingObject USE Sensor
      physics Physics {
      }
    }
    HingeJoint {
      jointParameters HingeJointParameters {
        axis 0 1 0
        anchor 0.05 0.06 0
      }
      device [
        RotationalMotor {
          name "wheel1"
        }
      ]
      endPoint Solid {
        translation 0.05 0.06 0
        rotation 1 0 0 1.5708
        children [
          Shape {
            appearance PBRAppearance {
              baseColor 0 1 0
              roughness 1
              metalness 0
            }
            geometry DEF Wheel_Geometry Cylinder {
              height 0.02
              radius 0.04
            }
          }
        ]
        boundingObject USE Wheel_Geometry
        physics Physics {
        }
      }
    }
    HingeJoint {
      jointParameters HingeJointParameters {
        axis 0 1 0
        anchor 0.05 -0.06 1.22354e-07
      }
      device [
        RotationalMotor {
          name "wheel2"
        }
      ]
      endPoint Solid {
        translation 0.05 -0.06 1.22354e-07
        rotation 0.9999999999999998 -9.589759999999996e-09 -9.589789999999996e-09 1.5707953071795862
        children [
          Shape {
            appearance PBRAppearance {
              baseColor 0 1 0
              roughness 1
              metalness 0
            }
            geometry Cylinder {
              height 0.02
              radius 0.04
            }
          }
        ]
        name "solid(1)"
        boundingObject USE Wheel_Geometry
        physics Physics {
        }
      }
    }
    HingeJoint {
      jointParameters HingeJointParameters {
        axis 0 1 0
        anchor -0.05 0.06 4.68944e-14
      }
      device [
        RotationalMotor {
          name "wheel3"
        }
      ]
      endPoint Solid {
        translation -0.05 0.06000000000000005 4.68944e-14
        rotation 0.9999999999999998 -9.589759999999996e-09 -9.589789999999996e-09 1.5707953071795862
        children [
          Shape {
            appearance PBRAppearance {
              baseColor 0 1 0
              roughness 1
              metalness 0
            }
            geometry Cylinder {
              height 0.02
              radius 0.04
            }
          }
        ]
        name "solid(2)"
        boundingObject USE Wheel_Geometry
        physics Physics {
        }
      }
    }
    HingeJoint {
      jointParameters HingeJointParameters {
        axis 0 1 0
        anchor -0.05 -0.06 1.22354e-07
      }
      device [
        RotationalMotor {
          name "wheel4"
        }
      ]
      endPoint Solid {
        translation -0.05 -0.06000000000000005 1.22354e-07
        rotation 0.9999999999999998 -9.589759999999996e-09 -9.589789999999996e-09 1.5707953071795862
        children [
          Shape {
            appearance PBRAppearance {
              baseColor 0 1 0
              roughness 1
              metalness 0
            }
            geometry Cylinder {
              height 0.02
              radius 0.04
            }
          }
        ]
        name "solid(3)"
        boundingObject USE Wheel_Geometry
        physics Physics {
        }
      }
    }
    DEF Body Shape {
      appearance PBRAppearance {
        baseColor 1 0 0
        roughness 1
        metalness 0
      }
      geometry DEF Body_Geometry Box {
        size 0.2 0.1 0.05
      }
    }
  ]
  boundingObject USE Body_Geometry
  physics Physics {
  }
  controller "four_wheeled_collision_avoidance"
}
